# 错误处理

在Go中没有`try`的操作, 错误通过函数返回给上层函数, 好处是避免漏掉本应该处理的错误, 弊端就是代码啰嗦

## 1. 错误和异常

错误: 是我们意料之中的, 如链接超时

异常: 意料之外的错误, 如空指针

Go中, 错误是`error`类型, 可以被函数变量传递

## 2. 惯例

```golang
if res, err := someFunc(); err != nil {
    // no error , do something
    fmt.Println(res)
}
```

## 3. 错误类型

1. Go中, 错误是一个接口

    ```golang
    type error interface {
        Error() string
    }
    ```

2. 只要实现了`Error() string`方法的都可以被称为一个error类型.

3. 打印错误时就是调用`Error()`方法

4. Go中, 创建一个错误可以使用`errors` `fmt`包

    ```golang
    import (
            "errors"
            "fmt"
    )

    func main() {
        err1 := errors.New("一个错误")
        fmt.Println(err1)

        fmt.Printf("%T\n", err1) // *errors.errorString

        err2 := fmt.Errorf("错误的信息%d", 100)
        fmt.Println(err2)
        fmt.Printf("%T\n", err2)
    }
    ```

## 4. 错误类型表示

1. error 是接口类型, 因此我们可以使用断言来对error进行检查

    ```golang
    package main

    import (
        "net"
        "fmt"
    )

    func main() {
        addr, err := net.LookupHost("www.不知道啥网址.com")

        if ins, ok := err.(*net.DNSError); ok{
            if ins.Timeout() {
                fmt.Println("操作超时")
            }else if ins.Temporary(){
                fmt.Println("临时性错误")
            }else{
                fmt.Println("通常错误")
            }
        }
    }

    ```

2. 对error进行值的比较

    ```golang
    package main

    import (
        "fmt"
        "filepath"
    )

    func main() {
        files, err := filepath.Glob("[")
        if err != nil && err == filepath.ErrBadPattern {
            fmt.Println(err)
            return 
        }
        fmt.Println(files)
    }
    ```

3. 不要忽略错误 `_`

## 5. 自定义错误

`errors.New` 和 `fmt.Errorf()` 能够得到一个错误对象

也可以自己定义错误

```golang

type MyError struct {
    msg     string
    where   string
}

func (e *MyError) Error() string {
    return fmt.Sprintf("I'm at %s, when %s happened", e.where, e.msg)
}

func (e *MyError) WhereAmI() string {
    return e.where
}

func getLost(path string) (bool, error){
    if path == "shanghai" {
        return true, nil
    }

    e := &MyError{msg: "something", where:path}

    return false, e
}

func main() {

    if amILost, err := getLost("beijing"); err {
        if ins, ok := err.(*MyError); ok{
            fmt.Println(ins.where)
        }
    }
    
}
```

## 6. 异常

`panic()`和`recover()`

Go中引入两个内置函数panic和recover来触发和终止异常处理流程, 同时引入关键词`defer`来延迟执行defer后面的函数.

2. panic

    1. panic是内建函数, 其参数是任意类型的, 如果调用了revocer则当做revocer的返回值

    2. 键入函数F中调用了panic函数, 会终止其后面要执行的代码, 在panic所在函数F内如果存在已经被defer函数列表, 按照defer的逆序执行(还没有被defer的函数不会被defer), 因此recover也要写在会发生panic的函数之前defer

    ```golang
    func goDeferPanic() {
        defer fmt.Println("defer1...") // 执行
        fmt.Println("函数开始")
        panic("panic....")
        defer fmt.Println("defer2...") // 不执行
    }
    ```

    3. 返回函数F的调用者G, 在G中, 调用函数F语句之后的代码不会执行, 假如函数G中存在要执行的defer函数列表, 按照defer的逆序执行, 这里的defer有点类似于try中的finally

    4. 直到goroutine整个退出, 并报告错误

3. revocer

    1. recover也是内建函数

    2. 用来控制一个goroutine的panic行为, 捕获panic, 从而影响应用的行为

    3. 一般这么使用

        - 在defer函数中, 通过recever来终止一个goroutine的panic过程, 从而恢复正常到吗的执行

        - 可以通过panic传递的error

        > Go通过panic抛出的异常可以被recover捕获

    4. recover只能在defer中被调用

    ```golang
    func goPanic() {
        defer func() {
            if n := recover(); n != nil {
                
            }
        }()

        fmt.Println("gofer is going to be panic")

        panic("gofer is panic ...")

    }

    func goRecover() {
        defer fmt.Println("结束")
        defer func() {
            if n := recover(); n != nil {
                fmt.Printf("%T\n", n)
                fmt.Println("found a panic gofer recovering ...")
            }
        }() // 由于goPanic自己捕获了异常, recover()返回值为nil

        goPanic()
    }
    ```

## 7. 处理错误场景

1. 失败的原因只有一种, 使用bool代替error

2. 没有失败, 不使用error

3. error放在返回值最后

4. 使用变量定义异常, 异常变量需要见名知意

5. 错误传递时, 都加上日志

6. 使用defer处理错误

## 8. 处理异常场景

1. 空指针引用

2. 下标越界

3. 零除

4. switch中不该出现的分支

5. 输出不应该引起函数错误
